<?xml version="1.0" ?>
<sdf version="1.6">
  <world name="spring_world">

    <plugin name='ignition::gazebo::systems::Physics' filename='libignition-gazebo-physics-system.so'/>
    <plugin name='ignition::gazebo::systems::UserCommands' filename='libignition-gazebo-user-commands-system.so'/>
    <plugin name='ignition::gazebo::systems::SceneBroadcaster' filename='libignition-gazebo-scene-broadcaster-system.so'/>
    <plugin name='ignition::gazebo::systems::Sensors' filename='libignition-gazebo-sensors-system.so'>
      <render_engine>ogre2</render_engine>
    </plugin>
    <plugin name="ignition::gazebo::systems::Imu" filename="libignition-gazebo-imu-system.so"/>
    <plugin name="ignition::gazebo::systems::NavSat" filename="libignition-gazebo-navsat-system.so"/>

    <model name='ground_plane'>
      <static>true</static>
      <link name='link'>
        <collision name='collision'>
          <geometry>
            <plane>
              <normal>0.0 0.0 1</normal>
              <size>100 100</size>
            </plane>
          </geometry>
        </collision>
        <visual name='visual'>
          <geometry>
            <plane>
              <normal>0.0 0.0 1</normal>
              <size>100 100</size>
            </plane>
          </geometry>
          <material>
            <ambient>0.8 0.8 0.8 1</ambient>
            <diffuse>0.8 0.8 0.8 1</diffuse>
          </material>
        </visual>
      </link>
      <pose>0 0 0 0 0 0</pose>
    </model>

    <!-- ADJACENT FRICTION PATCHES (in increasing friction order) -->
    
    <!-- Ultra Slippery Ice Patch (mu=0.01) -->
    <model name="patch_ice">
      <static>true</static>
      <pose>-6 6 0.01 0 0 0</pose>
      <link name="patch_link">
        <collision name="collision">
          <geometry>
            <box><size>3 3 0.01</size></box>
          </geometry>
          <surface>
            <friction><ode><mu>0.01</mu><mu2>0.01</mu2></ode></friction>
          </surface>
        </collision>
        <visual name="visual">
          <geometry><box><size>3 3 0.01</size></box></geometry>
          <material><ambient>0.7 0.7 1.0 0.8</ambient><diffuse>0.7 0.7 1.0 0.8</diffuse></material>
        </visual>
      </link>
    </model>

    <!-- Low Friction Patch (mu=0.2) -->
    <model name="patch_low_friction">
      <static>true</static>
      <pose>-3 6 0.01 0 0 0</pose>
      <link name="patch_link">
        <collision name="collision">
          <geometry>
            <box><size>3 3 0.01</size></box>
          </geometry>
          <surface>
            <friction><ode><mu>0.2</mu><mu2>0.2</mu2></ode></friction>
          </surface>
        </collision>
        <visual name="visual">
          <geometry><box><size>3 3 0.01</size></box></geometry>
          <material><ambient>0.1 0.1 0.8 1</ambient><diffuse>0.1 0.1 0.8 1</diffuse></material>
        </visual>
      </link>
    </model>

    <!-- Medium Friction Patch (mu=3.0) -->
    <model name="patch_medium_friction">
      <static>true</static>
      <pose>0 6 0.01 0 0 0</pose>
      <link name="patch_link">
        <collision name="collision">
          <geometry>
            <box><size>3 3 0.01</size></box>
          </geometry>
          <surface>
            <friction><ode><mu>3.0</mu><mu2>3.0</mu2></ode></friction>
          </surface>
        </collision>
        <visual name="visual">
          <geometry><box><size>3 3 0.01</size></box></geometry>
          <material><ambient>0.1 0.6 0.1 1</ambient><diffuse>0.1 0.6 0.1 1</diffuse></material>
        </visual>
      </link>
    </model>

    <!-- High Friction Patch (mu=6.0) -->
    <model name="resistance_patch">
      <static>true</static>
      <pose>3 6 0.01 0 0 0</pose>
      <link name="patch_link">
        <collision name="collision">
          <geometry>
            <box><size>3 3 0.01</size></box>
          </geometry>
          <surface>
            <friction><ode><mu>6.0</mu><mu2>6.0</mu2></ode></friction>
          </surface>
        </collision>
        <visual name="visual">
          <geometry><box><size>3 3 0.01</size></box></geometry>
          <material><ambient>0.7 0.3 0.3 1</ambient><diffuse>0.7 0.3 0.3 1</diffuse></material>
        </visual>
      </link>
    </model>

    <!-- Very High Friction Patch (mu=10.0) -->
    <model name="patch_high_friction">
      <static>true</static>
      <pose>6 6 0.01 0 0 0</pose>
      <link name="patch_link">
        <collision name="collision">
          <geometry>
            <box><size>3 3 0.01</size></box>
          </geometry>
          <surface>
            <friction><ode><mu>10.0</mu><mu2>10.0</mu2></ode></friction>
          </surface>
        </collision>
        <visual name="visual">
          <geometry><box><size>3 3 0.01</size></box></geometry>
          <material><ambient>0.8 0.1 0.1 1</ambient><diffuse>0.8 0.1 0.1 1</diffuse></material>
        </visual>
      </link>
    </model>

    <!-- COLLECTION OF PLIABLE OBSTACLES WITH VARYING PROPERTIES -->

    <!-- Original Springy Bush Model -->
    <model name="bush_spring">
      <static>false</static>
      <pose>-6 0 0.5 0 0 0</pose>
      <link name="bush_link">
        <collision name="collision">
          <geometry>
            <cylinder>
              <radius>0.5</radius>
              <length>1.0</length>
            </cylinder>
          </geometry>
          <surface>
            <contact>
              <ode>
                <kp>100.0</kp>         <!-- Spring stiffness -->
                <kd>5.0</kd>           <!-- Damping -->
                <max_vel>0.5</max_vel> <!-- Optional: limit collision velocity -->
                <min_depth>0.001</min_depth> <!-- Optional: minimum penetration before contact triggers -->
              </ode>
            </contact>
            <friction>
              <ode>
                <mu>0.2</mu>
                <mu2>0.2</mu2>
              </ode>
            </friction>
          </surface>
        </collision>
        <visual name="visual">
          <geometry>
            <cylinder>
              <radius>0.5</radius>
              <length>1.0</length>
            </cylinder>
          </geometry>
          <material>
            <ambient>0.2 0.8 0.2 1</ambient>
            <diffuse>0.2 0.8 0.2 1</diffuse>
          </material>
        </visual>
        <sensor name="contact_sensor" type="contact">
          <always_on>1</always_on>
          <update_rate>30</update_rate>
          <contact>
            <collision>collision</collision>
          </contact>
        </sensor>
      </link>
      <joint name="spring_joint" type="prismatic">
        <parent>world</parent>
        <child>bush_link</child>
        <axis>
          <xyz>0 0 1</xyz>
          <limit>
            <lower>-0.1</lower>
            <upper>0.1</upper>
          </limit>
          <dynamics>
            <spring_stiffness>10.0</spring_stiffness>
            <damping>5.0</damping>
          </dynamics>
        </axis>
      </joint>
    </model>

    Soft Pliable Cylinder with Multiple Joints
    <model name="soft_cylinder">
      <static>false</static>
      <pose>-3 0 0.5 0 0 0</pose>
      <link name="base_link">
        <collision name="collision">
          <geometry>
            <cylinder>
              <radius>0.5</radius>
              <length>0.2</length>
            </cylinder>
          </geometry>
          <surface>
            <contact>
              <ode>
                <kp>50.0</kp>         <!-- Lower stiffness -->
                <kd>2.0</kd>          <!-- Lower damping -->
              </ode>
            </contact>
            <friction>
              <ode>
                <mu>0.2</mu>
                <mu2>0.2</mu2>
              </ode>
            </friction>
          </surface>
        </collision>
        <visual name="visual">
          <geometry>
            <cylinder>
              <radius>0.5</radius>
              <length>0.2</length>
            </cylinder>
          </geometry>
          <material>
            <ambient>0.8 0.2 0.8 1</ambient>
            <diffuse>0.8 0.2 0.8 1</diffuse>
          </material>
        </visual>
        <inertial>
          <mass>0.5</mass>
        </inertial>
      </link>
      
      <!-- Middle section -->
      <link name="middle_link">
        <pose>0 0 0.2 0 0 0</pose>
        <collision name="collision">
          <geometry>
            <cylinder>
              <radius>0.5</radius>
              <length>0.2</length>
            </cylinder>
          </geometry>
        </collision>
        <visual name="visual">
          <geometry>
            <cylinder>
              <radius>0.5</radius>
              <length>0.2</length>
            </cylinder>
          </geometry>
          <material>
            <ambient>0.8 0.3 0.8 1</ambient>
            <diffuse>0.8 0.3 0.8 1</diffuse>
          </material>
        </visual>
        <inertial>
          <mass>0.5</mass>
        </inertial>
      </link>
      
      <!-- Top section -->
      <link name="top_link">
        <pose>0 0 0.4 0 0 0</pose>
        <collision name="collision">
          <geometry>
            <cylinder>
              <radius>0.5</radius>
              <length>0.2</length>
            </cylinder>
          </geometry>
        </collision>
        <visual name="visual">
          <geometry>
            <cylinder>
              <radius>0.5</radius>
              <length>0.2</length>
            </cylinder>
          </geometry>
          <material>
            <ambient>0.8 0.4 0.8 1</ambient>
            <diffuse>0.8 0.4 0.8 1</diffuse>
          </material>
        </visual>
        <inertial>
          <mass>0.5</mass>
        </inertial>
      </link>
      
      <!-- Base to ground joint -->
      <joint name="base_joint" type="ball">
        <parent>world</parent>
        <child>base_link</child>
        <axis>
          <xyz>1 0 0</xyz>
          <dynamics>
            <damping>1.0</damping>
            <spring_stiffness>5.0</spring_stiffness>
          </dynamics>
        </axis>
      </joint>
      
      <!-- Middle joint -->
      <joint name="middle_joint" type="universal">
        <parent>base_link</parent>
        <child>middle_link</child>
        <pose>0 0 0.1 0 0 0</pose>
        <axis>
          <xyz>1 0 0</xyz>
          <dynamics>
            <damping>0.5</damping>
            <spring_stiffness>2.0</spring_stiffness>
          </dynamics>
          <limit>
            <lower>-0.5</lower>
            <upper>0.5</upper>
          </limit>
        </axis>
        <axis2>
          <xyz>0 1 0</xyz>
          <dynamics>
            <damping>0.5</damping>
            <spring_stiffness>2.0</spring_stiffness>
          </dynamics>
          <limit>
            <lower>-0.5</lower>
            <upper>0.5</upper>
          </limit>
        </axis2>
      </joint>
      
      <!-- Top joint -->
      <joint name="top_joint" type="universal">
        <parent>middle_link</parent>
        <child>top_link</child>
        <pose>0 0 0.1 0 0 0</pose>
        <axis>
          <xyz>1 0 0</xyz>
          <dynamics>
            <damping>0.2</damping>
            <spring_stiffness>1.0</spring_stiffness>
          </dynamics>
          <limit>
            <lower>-0.7</lower>
            <upper>0.7</upper>
          </limit>
        </axis>
        <axis2>
          <xyz>0 1 0</xyz>
          <dynamics>
            <damping>0.2</damping>
            <spring_stiffness>1.0</spring_stiffness>
          </dynamics>
          <limit>
            <lower>-0.7</lower>
            <upper>0.7</upper>
          </limit>
        </axis2>
      </joint>
    </model>

    <!-- Bendable Cylinder with Revolute Joints -->
    <model name="bendable_cylinder">
      <static>false</static>
      <pose>0 0 0.5 0 0 0</pose>
      <link name="base_link">
        <collision name="collision">
          <geometry>
            <cylinder>
              <radius>0.5</radius>
              <length>0.25</length>
            </cylinder>
          </geometry>
          <surface>
            <contact>
              <ode>
                <kp>1000.0</kp>
                <kd>100.0</kd>
              </ode>
            </contact>
          </surface>
        </collision>
        <visual name="visual">
          <geometry>
            <cylinder>
              <radius>0.5</radius>
              <length>0.25</length>
            </cylinder>
          </geometry>
          <material>
            <ambient>0.2 0.5 0.7 1</ambient>
            <diffuse>0.2 0.5 0.7 1</diffuse>
          </material>
        </visual>
        <inertial>
          <mass>1.0</mass>
        </inertial>
      </link>
      
      <link name="section_1">
        <pose>0 0 0.25 0 0 0</pose>
        <collision name="collision">
          <geometry>
            <cylinder>
              <radius>0.45</radius>
              <length>0.25</length>
            </cylinder>
          </geometry>
        </collision>
        <visual name="visual">
          <geometry>
            <cylinder>
              <radius>0.45</radius>
              <length>0.25</length>
            </cylinder>
          </geometry>
          <material>
            <ambient>0.3 0.5 0.7 1</ambient>
            <diffuse>0.3 0.5 0.7 1</diffuse>
          </material>
        </visual>
        <inertial>
          <mass>0.8</mass>
        </inertial>
      </link>
      
      <link name="section_2">
        <pose>0 0 0.5 0 0 0</pose>
        <collision name="collision">
          <geometry>
            <cylinder>
              <radius>0.4</radius>
              <length>0.25</length>
            </cylinder>
          </geometry>
        </collision>
        <visual name="visual">
          <geometry>
            <cylinder>
              <radius>0.4</radius>
              <length>0.25</length>
            </cylinder>
          </geometry>
          <material>
            <ambient>0.4 0.5 0.7 1</ambient>
            <diffuse>0.4 0.5 0.7 1</diffuse>
          </material>
        </visual>
        <inertial>
          <mass>0.6</mass>
        </inertial>
      </link>
      
      <link name="section_3">
        <pose>0 0 0.75 0 0 0</pose>
        <collision name="collision">
          <geometry>
            <cylinder>
              <radius>0.35</radius>
              <length>0.25</length>
            </cylinder>
          </geometry>
        </collision>
        <visual name="visual">
          <geometry>
            <cylinder>
              <radius>0.35</radius>
              <length>0.25</length>
            </cylinder>
          </geometry>
          <material>
            <ambient>0.5 0.5 0.7 1</ambient>
            <diffuse>0.5 0.5 0.7 1</diffuse>
          </material>
        </visual>
        <inertial>
          <mass>0.4</mass>
        </inertial>
      </link>
      
      <!-- Fixed joint to world -->
      <joint name="world_joint" type="fixed">
        <parent>world</parent>
        <child>base_link</child>
      </joint>
      
      <!-- Revolute joints between sections -->
      <joint name="joint_1" type="revolute">
        <parent>base_link</parent>
        <child>section_1</child>
        <pose>0 0 0.125 0 0 0</pose>
        <axis>
          <xyz>1 0 0</xyz>
          <limit>
            <lower>-0.4</lower>
            <upper>0.4</upper>
          </limit>
          <dynamics>
            <spring_stiffness>50</spring_stiffness>
            <damping>5.0</damping>
          </dynamics>
        </axis>
      </joint>
      
      <joint name="joint_2" type="revolute">
        <parent>section_1</parent>
        <child>section_2</child>
        <pose>0 0 0.125 0 0 0</pose>
        <axis>
          <xyz>0 1 0</xyz>
          <limit>
            <lower>-0.4</lower>
            <upper>0.4</upper>
          </limit>
          <dynamics>
            <spring_stiffness>40</spring_stiffness>
            <damping>4.0</damping>
          </dynamics>
        </axis>
      </joint>
      
      <joint name="joint_3" type="revolute">
        <parent>section_2</parent>
        <child>section_3</child>
        <pose>0 0 0.125 0 0 0</pose>
        <axis>
          <xyz>1 0 0</xyz>
          <limit>
            <lower>-0.4</lower>
            <upper>0.4</upper>
          </limit>
          <dynamics>
            <spring_stiffness>30</spring_stiffness>
            <damping>3.0</damping>
          </dynamics>
        </axis>
      </joint>
    </model>
    
    <!-- Bendy Tree with Soft and Hard Sections -->
    <model name="bendy_tree">
      <static>false</static>
      <pose>3 0 0 0 0 0</pose>
      
      <!-- Trunk base - fixed to ground -->
      <link name="trunk_base">
        <pose>0 0 0.5 0 0 0</pose>
        <collision name="collision">
          <geometry>
            <cylinder>
              <radius>0.4</radius>
              <length>1.0</length>
            </cylinder>
          </geometry>
          <surface>
            <friction>
              <ode>
                <mu>1.0</mu>
                <mu2>1.0</mu2>
              </ode>
            </friction>
          </surface>
        </collision>
        <visual name="visual">
          <geometry>
            <cylinder>
              <radius>0.4</radius>
              <length>1.0</length>
            </cylinder>
          </geometry>
          <material>
            <ambient>0.6 0.4 0.2 1</ambient>
            <diffuse>0.6 0.4 0.2 1</diffuse>
          </material>
        </visual>
        <inertial>
          <mass>5.0</mass>
        </inertial>
      </link>
      
      <!-- Middle trunk section - more flexible -->
      <link name="trunk_middle">
        <pose>0 0 1.25 0 0 0</pose>
        <collision name="collision">
          <geometry>
            <cylinder>
              <radius>0.3</radius>
              <length>0.5</length>
            </cylinder>
          </geometry>
        </collision>
        <visual name="visual">
          <geometry>
            <cylinder>
              <radius>0.3</radius>
              <length>0.5</length>
            </cylinder>
          </geometry>
          <material>
            <ambient>0.6 0.4 0.2 1</ambient>
            <diffuse>0.6 0.4 0.2 1</diffuse>
          </material>
        </visual>
        <inertial>
          <mass>3.0</mass>
        </inertial>
      </link>
      
      <!-- Upper trunk section - most flexible -->
      <link name="trunk_upper">
        <pose>0 0 1.75 0 0 0</pose>
        <collision name="collision">
          <geometry>
            <cylinder>
              <radius>0.2</radius>
              <length>0.5</length>
            </cylinder>
          </geometry>
        </collision>
        <visual name="visual">
          <geometry>
            <cylinder>
              <radius>0.2</radius>
              <length>0.5</length>
            </cylinder>
          </geometry>
          <material>
            <ambient>0.6 0.4 0.2 1</ambient>
            <diffuse>0.6 0.4 0.2 1</diffuse>
          </material>
        </visual>
        <inertial>
          <mass>1.5</mass>
        </inertial>
      </link>
      
      <!-- Left branch -->
      <link name="branch_left">
        <pose>0.4 0 1.75 0 0 0</pose>
        <collision name="collision">
          <geometry>
            <cylinder>
              <radius>0.1</radius>
              <length>0.8</length>
            </cylinder>
          </geometry>
        </collision>
        <visual name="visual">
          <geometry>
            <cylinder>
              <radius>0.1</radius>
              <length>0.8</length>
            </cylinder>
          </geometry>
          <material>
            <ambient>0.6 0.4 0.2 1</ambient>
            <diffuse>0.6 0.4 0.2 1</diffuse>
          </material>
        </visual>
        <inertial>
          <mass>0.8</mass>
        </inertial>
      </link>
      
      <!-- Right branch -->
      <link name="branch_right">
        <pose>-0.4 0 1.75 0 0 0</pose>
        <collision name="collision">
          <geometry>
            <cylinder>
              <radius>0.1</radius>
              <length>0.8</length>
            </cylinder>
          </geometry>
        </collision>
        <visual name="visual">
          <geometry>
            <cylinder>
              <radius>0.1</radius>
              <length>0.8</length>
            </cylinder>
          </geometry>
          <material>
            <ambient>0.6 0.4 0.2 1</ambient>
            <diffuse>0.6 0.4 0.2 1</diffuse>
          </material>
        </visual>
        <inertial>
          <mass>0.8</mass>
        </inertial>
      </link>
      
      <!-- Fixed base to world -->
      <joint name="world_joint" type="fixed">
        <parent>world</parent>
        <child>trunk_base</child>
      </joint>
      
      <!-- Base to middle trunk joint -->
      <joint name="trunk_middle_joint" type="revolute">
        <parent>trunk_base</parent>
        <child>trunk_middle</child>
        <pose>0 0 0.25 0 0 0</pose>
        <axis>
          <xyz>1 0 0</xyz>
          <limit>
            <lower>-0.3</lower>
            <upper>0.3</upper>
          </limit>
          <dynamics>
            <spring_stiffness>200</spring_stiffness>
            <damping>20.0</damping>
          </dynamics>
        </axis>
      </joint>
      
      <!-- Middle to upper trunk joint -->
      <joint name="trunk_upper_joint" type="universal">
        <parent>trunk_middle</parent>
        <child>trunk_upper</child>
        <pose>0 0 0.25 0 0 0</pose>
        <axis>
          <xyz>1 0 0</xyz>
          <limit>
            <lower>-0.5</lower>
            <upper>0.5</upper>
          </limit>
          <dynamics>
            <spring_stiffness>100</spring_stiffness>
            <damping>10.0</damping>
          </dynamics>
        </axis>
        <axis2>
          <xyz>0 1 0</xyz>
          <limit>
            <lower>-0.5</lower>
            <upper>0.5</upper>
          </limit>
          <dynamics>
            <spring_stiffness>100</spring_stiffness>
            <damping>10.0</damping>
          </dynamics>
        </axis2>
      </joint>
      
      <!-- Left branch joint -->
      <joint name="branch_left_joint" type="universal">
        <parent>trunk_upper</parent>
        <child>branch_left</child>
        <pose>0 0 0 0 1.5708 0</pose>
        <axis>
          <xyz>0 1 0</xyz>
          <limit>
            <lower>-0.8</lower>
            <upper>0.8</upper>
          </limit>
          <dynamics>
            <spring_stiffness>50</spring_stiffness>
            <damping>5.0</damping>
          </dynamics>
        </axis>
        <axis2>
          <xyz>0 0 1</xyz>
          <limit>
            <lower>-0.8</lower>
            <upper>0.8</upper>
          </limit>
          <dynamics>
            <spring_stiffness>50</spring_stiffness>
            <damping>5.0</damping>
          </dynamics>
        </axis2>
      </joint>
      
      <!-- Right branch joint -->
      <joint name="branch_right_joint" type="universal">
        <parent>trunk_upper</parent>
        <child>branch_right</child>
        <pose>0 0 0 0 -1.5708 0</pose>
        <axis>
          <xyz>0 1 0</xyz>
          <limit>
            <lower>-0.8</lower>
            <upper>0.8</upper>
          </limit>
          <dynamics>
            <spring_stiffness>50</spring_stiffness>
            <damping>5.0</damping>
          </dynamics>
        </axis>
        <axis2>
          <xyz>0 0 1</xyz>
          <limit>
            <lower>-0.8</lower>
            <upper>0.8</upper>
          </limit>
          <dynamics>
            <spring_stiffness>50</spring_stiffness>
            <damping>5.0</damping>
          </dynamics>
        </axis2>
      </joint>
    </model>

    <!-- Super Flexible Obstacle - Rubber-like -->
    <model name="rubber_post">
      <static>false</static>
      <pose>6 0 0 0 0 0</pose>
      
      <!-- Base anchor -->
      <link name="base">
        <pose>0 0 0.25 0 0 0</pose>
        <collision name="collision">
          <geometry>
            <cylinder>
              <radius>0.3</radius>
              <length>0.5</length>
            </cylinder>
          </geometry>
          <surface>
            <friction>
              <ode>
                <mu>1.0</mu>
                <mu2>1.0</mu2>
              </ode>
            </friction>
          </surface>
        </collision>
        <visual name="visual">
          <geometry>
            <cylinder>
              <radius>0.3</radius>
              <length>0.5</length>
            </cylinder>
          </geometry>
          <material>
            <ambient>0.1 0.1 0.1 1</ambient>
            <diffuse>0.1 0.1 0.1 1</diffuse>
          </material>
        </visual>
        <inertial>
          <mass>3.0</mass>
        </inertial>
      </link>
      
      <!-- Flexible segments -->
      <link name="segment1">
        <pose>0 0 0.75 0 0 0</pose>
        <collision name="collision">
          <geometry>
            <cylinder>
              <radius>0.2</radius>
              <length>0.5</length>
            </cylinder>
          </geometry>
        </collision>
        <visual name="visual">
          <geometry>
            <cylinder>
              <radius>0.2</radius>
              <length>0.5</length>
            </cylinder>
          </geometry>
          <material>
            <ambient>0.2 0.2 0.2 1</ambient>
            <diffuse>0.2 0.2 0.2 1</diffuse>
          </material>
        </visual>
        <inertial>
          <mass>0.5</mass>
        </inertial>
      </link>
      
      <link name="segment2">
        <pose>0 0 1.25 0 0 0</pose>
        <collision name="collision">
          <geometry>
            <cylinder>
              <radius>0.2</radius>
              <length>0.5</length>
            </cylinder>
          </geometry>
        </collision>
        <visual name="visual">
          <geometry>
            <cylinder>
              <radius>0.2</radius>
              <length>0.5</length>
            </cylinder>
          </geometry>
          <material>
            <ambient>0.3 0.3 0.3 1</ambient>
            <diffuse>0.3 0.3 0.3 1</diffuse>
          </material>
        </visual>
        <inertial>
          <mass>0.5</mass>
        </inertial>
      </link>
      
      <link name="segment3">
        <pose>0 0 1.75 0 0 0</pose>
        <collision name="collision">
          <geometry>
            <cylinder>
              <radius>0.2</radius>
              <length>0.5</length>
            </cylinder>
          </geometry>
        </collision>
        <visual name="visual">
          <geometry>
            <cylinder>
              <radius>0.2</radius>
              <length>0.5</length>
            </cylinder>
          </geometry>
          <material>
            <ambient>0.4 0.4 0.4 1</ambient>
            <diffuse>0.4 0.4 0.4 1</diffuse>
          </material>
        </visual>
        <inertial>
          <mass>0.5</mass>
        </inertial>
      </link>
      
      <!-- Fixed joint to world -->
      <joint name="world_joint" type="fixed">
        <parent>world</parent>
        <child>base</child>
      </joint>
      
      <!-- Soft ball joints between segments -->
      <joint name="joint1" type="ball">
        <parent>base</parent>
        <child>segment1</child>
        <pose>0 0 0.25 0 0 0</pose>
        <axis>
          <xyz>1 0 0</xyz>
          <dynamics>
            <damping>1.0</damping>
            <spring_stiffness>10.0</spring_stiffness>
          </dynamics>
        </axis>
      </joint>
      
      <joint name="joint2" type="ball">
        <parent>segment1</parent>
        <child>segment2</child>
        <pose>0 0 0.25 0 0 0</pose>
        <axis>
          <xyz>1 0 0</xyz>
          <dynamics>
            <damping>0.8</damping>
            <spring_stiffness>8.0</spring_stiffness>
          </dynamics>
        </axis>
      </joint>
      
      <joint name="joint3" type="ball">
        <parent>segment2</parent>
        <child>segment3</child>
        <pose>0 0 0.25 0 0 0</pose>
        <axis>
          <xyz>1 0 0</xyz>
          <dynamics>
            <damping>0.5</damping>
            <spring_stiffness>5.0</spring_stiffness>
          </dynamics>
        </axis>
      </joint>
    </model>
  </world>
</sdf>